
C:\Users\angel\AppData\Local\Programs\Python\Python312\python.exe: can't open file 'C:\\Windows\\System32\\run_waitress.py': [Errno 2] No such file or directory
WARNING:django.request:Not Found: /Oadw
WARNING:django.request:Not Found: /favicon.ico
WARNING:django.request:Not Found: /Oadw
ERROR:django.request:Internal Server Error: /OICSec/
Traceback (most recent call last):
  File "D:\ProyectosPython\PSCG-Management-Monitoring-and-Control-Platform\.venv\Lib\site-packages\django\contrib\sessions\backends\base.py", line 187, in _get_session
    return self._session_cache
           ^^^^^^^^^^^^^^^^^^^
AttributeError: 'SessionStore' object has no attribute '_session_cache'

During handling of the above exception, another exception occurred:

Traceback (most recent call last):
  File "D:\ProyectosPython\PSCG-Management-Monitoring-and-Control-Platform\.venv\Lib\site-packages\django\db\backends\base\base.py", line 275, in ensure_connection
    self.connect()
  File "D:\ProyectosPython\PSCG-Management-Monitoring-and-Control-Platform\.venv\Lib\site-packages\django\utils\asyncio.py", line 26, in inner
    return func(*args, **kwargs)
           ^^^^^^^^^^^^^^^^^^^^^
  File "D:\ProyectosPython\PSCG-Management-Monitoring-and-Control-Platform\.venv\Lib\site-packages\django\db\backends\base\base.py", line 256, in connect
    self.connection = self.get_new_connection(conn_params)
                      ^^^^^^^^^^^^^^^^^^^^^^^^^^^^^^^^^^^^
  File "D:\ProyectosPython\PSCG-Management-Monitoring-and-Control-Platform\.venv\Lib\site-packages\django\utils\asyncio.py", line 26, in inner
    return func(*args, **kwargs)
           ^^^^^^^^^^^^^^^^^^^^^
  File "D:\ProyectosPython\PSCG-Management-Monitoring-and-Control-Platform\.venv\Lib\site-packages\django\db\backends\mysql\base.py", line 256, in get_new_connection
    connection = Database.connect(**conn_params)
                 ^^^^^^^^^^^^^^^^^^^^^^^^^^^^^^^
  File "D:\ProyectosPython\PSCG-Management-Monitoring-and-Control-Platform\.venv\Lib\site-packages\MySQLdb\__init__.py", line 121, in Connect
    return Connection(*args, **kwargs)
           ^^^^^^^^^^^^^^^^^^^^^^^^^^^
  File "D:\ProyectosPython\PSCG-Management-Monitoring-and-Control-Platform\.venv\Lib\site-packages\MySQLdb\connections.py", line 195, in __init__
    super().__init__(*args, **kwargs2)
MySQLdb.OperationalError: (2002, "Can't connect to server on '127.0.0.1' (10061)")

The above exception was the direct cause of the following exception:

Traceback (most recent call last):
  File "D:\ProyectosPython\PSCG-Management-Monitoring-and-Control-Platform\.venv\Lib\site-packages\django\core\handlers\exception.py", line 55, in inner
    response = get_response(request)
               ^^^^^^^^^^^^^^^^^^^^^
  File "D:\ProyectosPython\PSCG-Management-Monitoring-and-Control-Platform\.venv\Lib\site-packages\django\core\handlers\base.py", line 197, in _get_response
    response = wrapped_callback(request, *callback_args, **callback_kwargs)
               ^^^^^^^^^^^^^^^^^^^^^^^^^^^^^^^^^^^^^^^^^^^^^^^^^^^^^^^^^^^^
  File "D:\ProyectosPython\PSCG-Management-Monitoring-and-Control-Platform\OICSec\views.py", line 42, in login_view
    if request.user.is_authenticated:
       ^^^^^^^^^^^^^^^^^^^^^^^^^^^^^
  File "D:\ProyectosPython\PSCG-Management-Monitoring-and-Control-Platform\.venv\Lib\site-packages\django\utils\functional.py", line 251, in inner
    self._setup()
  File "D:\ProyectosPython\PSCG-Management-Monitoring-and-Control-Platform\.venv\Lib\site-packages\django\utils\functional.py", line 404, in _setup
    self._wrapped = self._setupfunc()
                    ^^^^^^^^^^^^^^^^^
  File "D:\ProyectosPython\PSCG-Management-Monitoring-and-Control-Platform\.venv\Lib\site-packages\django\contrib\auth\middleware.py", line 33, in <lambda>
    request.user = SimpleLazyObject(lambda: get_user(request))
                                            ^^^^^^^^^^^^^^^^^
  File "D:\ProyectosPython\PSCG-Management-Monitoring-and-Control-Platform\.venv\Lib\site-packages\django\contrib\auth\middleware.py", line 13, in get_user
    request._cached_user = auth.get_user(request)
                           ^^^^^^^^^^^^^^^^^^^^^^
  File "D:\ProyectosPython\PSCG-Management-Monitoring-and-Control-Platform\.venv\Lib\site-packages\django\contrib\auth\__init__.py", line 209, in get_user
    user_id = _get_user_session_key(request)
              ^^^^^^^^^^^^^^^^^^^^^^^^^^^^^^
  File "D:\ProyectosPython\PSCG-Management-Monitoring-and-Control-Platform\.venv\Lib\site-packages\django\contrib\auth\__init__.py", line 62, in _get_user_session_key
    return get_user_model()._meta.pk.to_python(request.session[SESSION_KEY])
                                               ~~~~~~~~~~~~~~~^^^^^^^^^^^^^
  File "D:\ProyectosPython\PSCG-Management-Monitoring-and-Control-Platform\.venv\Lib\site-packages\django\contrib\sessions\backends\base.py", line 53, in __getitem__
    return self._session[key]
           ^^^^^^^^^^^^^
  File "D:\ProyectosPython\PSCG-Management-Monitoring-and-Control-Platform\.venv\Lib\site-packages\django\contrib\sessions\backends\base.py", line 192, in _get_session
    self._session_cache = self.load()
                          ^^^^^^^^^^^
  File "D:\ProyectosPython\PSCG-Management-Monitoring-and-Control-Platform\.venv\Lib\site-packages\django\contrib\sessions\backends\db.py", line 42, in load
    s = self._get_session_from_db()
        ^^^^^^^^^^^^^^^^^^^^^^^^^^^
  File "D:\ProyectosPython\PSCG-Management-Monitoring-and-Control-Platform\.venv\Lib\site-packages\django\contrib\sessions\backends\db.py", line 32, in _get_session_from_db
    return self.model.objects.get(
           ^^^^^^^^^^^^^^^^^^^^^^^
  File "D:\ProyectosPython\PSCG-Management-Monitoring-and-Control-Platform\.venv\Lib\site-packages\django\db\models\manager.py", line 87, in manager_method
    return getattr(self.get_queryset(), name)(*args, **kwargs)
           ^^^^^^^^^^^^^^^^^^^^^^^^^^^^^^^^^^^^^^^^^^^^^^^^^^^
  File "D:\ProyectosPython\PSCG-Management-Monitoring-and-Control-Platform\.venv\Lib\site-packages\django\db\models\query.py", line 645, in get
    num = len(clone)
          ^^^^^^^^^^
  File "D:\ProyectosPython\PSCG-Management-Monitoring-and-Control-Platform\.venv\Lib\site-packages\django\db\models\query.py", line 382, in __len__
    self._fetch_all()
  File "D:\ProyectosPython\PSCG-Management-Monitoring-and-Control-Platform\.venv\Lib\site-packages\django\db\models\query.py", line 1928, in _fetch_all
    self._result_cache = list(self._iterable_class(self))
                         ^^^^^^^^^^^^^^^^^^^^^^^^^^^^^^^^
  File "D:\ProyectosPython\PSCG-Management-Monitoring-and-Control-Platform\.venv\Lib\site-packages\django\db\models\query.py", line 91, in __iter__
    results = compiler.execute_sql(
              ^^^^^^^^^^^^^^^^^^^^^
  File "D:\ProyectosPython\PSCG-Management-Monitoring-and-Control-Platform\.venv\Lib\site-packages\django\db\models\sql\compiler.py", line 1560, in execute_sql
    cursor = self.connection.cursor()
             ^^^^^^^^^^^^^^^^^^^^^^^^
  File "D:\ProyectosPython\PSCG-Management-Monitoring-and-Control-Platform\.venv\Lib\site-packages\django\utils\asyncio.py", line 26, in inner
    return func(*args, **kwargs)
           ^^^^^^^^^^^^^^^^^^^^^
  File "D:\ProyectosPython\PSCG-Management-Monitoring-and-Control-Platform\.venv\Lib\site-packages\django\db\backends\base\base.py", line 316, in cursor
    return self._cursor()
           ^^^^^^^^^^^^^^
  File "D:\ProyectosPython\PSCG-Management-Monitoring-and-Control-Platform\.venv\Lib\site-packages\django\db\backends\base\base.py", line 292, in _cursor
    self.ensure_connection()
  File "D:\ProyectosPython\PSCG-Management-Monitoring-and-Control-Platform\.venv\Lib\site-packages\django\utils\asyncio.py", line 26, in inner
    return func(*args, **kwargs)
           ^^^^^^^^^^^^^^^^^^^^^
  File "D:\ProyectosPython\PSCG-Management-Monitoring-and-Control-Platform\.venv\Lib\site-packages\django\db\backends\base\base.py", line 274, in ensure_connection
    with self.wrap_database_errors:
  File "D:\ProyectosPython\PSCG-Management-Monitoring-and-Control-Platform\.venv\Lib\site-packages\django\db\utils.py", line 91, in __exit__
    raise dj_exc_value.with_traceback(traceback) from exc_value
  File "D:\ProyectosPython\PSCG-Management-Monitoring-and-Control-Platform\.venv\Lib\site-packages\django\db\backends\base\base.py", line 275, in ensure_connection
    self.connect()
  File "D:\ProyectosPython\PSCG-Management-Monitoring-and-Control-Platform\.venv\Lib\site-packages\django\utils\asyncio.py", line 26, in inner
    return func(*args, **kwargs)
           ^^^^^^^^^^^^^^^^^^^^^
  File "D:\ProyectosPython\PSCG-Management-Monitoring-and-Control-Platform\.venv\Lib\site-packages\django\db\backends\base\base.py", line 256, in connect
    self.connection = self.get_new_connection(conn_params)
                      ^^^^^^^^^^^^^^^^^^^^^^^^^^^^^^^^^^^^
  File "D:\ProyectosPython\PSCG-Management-Monitoring-and-Control-Platform\.venv\Lib\site-packages\django\utils\asyncio.py", line 26, in inner
    return func(*args, **kwargs)
           ^^^^^^^^^^^^^^^^^^^^^
  File "D:\ProyectosPython\PSCG-Management-Monitoring-and-Control-Platform\.venv\Lib\site-packages\django\db\backends\mysql\base.py", line 256, in get_new_connection
    connection = Database.connect(**conn_params)
                 ^^^^^^^^^^^^^^^^^^^^^^^^^^^^^^^
  File "D:\ProyectosPython\PSCG-Management-Monitoring-and-Control-Platform\.venv\Lib\site-packages\MySQLdb\__init__.py", line 121, in Connect
    return Connection(*args, **kwargs)
           ^^^^^^^^^^^^^^^^^^^^^^^^^^^
  File "D:\ProyectosPython\PSCG-Management-Monitoring-and-Control-Platform\.venv\Lib\site-packages\MySQLdb\connections.py", line 195, in __init__
    super().__init__(*args, **kwargs2)
django.db.utils.OperationalError: (2002, "Can't connect to server on '127.0.0.1' (10061)")
WARNING:django.request:Not Found: /favicon.ico
